[API 文档](http://nodejs.cn/api/)

## node.js 内置模块

- EventEmitter

  - 观察者模式 ( 对象之间的通信 )

    - addEventListener
    - removeEventListener

  - 调用 vs 抛事件
    - 关键在于"不知道被通知者存在" 【 私密性问题，任何对象都可以定义接收 】
    - 以及"没有人听还能继续下去"

[示例](/src/study.jk/2/class1/index.js)

## 异步：非阻塞 IO

- I/O 即 Input / Output, 一个系统的输入输出
- 阻塞 I/O 和非阻塞 I/O 的区别就在于 **系统接收 输入再到输出期间，能不能接收其他输入**。
  - 示例： 食堂打饭 vs 餐厅点餐[ 对于去吃饭的人： 排队打饭就是阻塞 I/O，点餐就是非阻塞 I/O]
  - 要点：确定一个 Input / Output 系统，思考在 I/O 过程中，能不能进行其他 I/O [比如：对于 餐厅厨师来讲，炒菜只能是一个一个的炒，所以是阻塞的]

[示例](/src/study.jk/2/class2/index.js)

## 异步：异步编程之 callback

- 回掉函数格式规范
  - error-first callback
  - Node-style callback
- 第一个参数是 error,后面的参数才是结果

## 异步：异步编程之 promise

- 是一个承诺，当前事件循环得不到结果，但未来事件循环会给你结果
- 是个状态机制 pending 到 结果只能选择 resolve/reject 之一

  - pending [等待] 状态
    - fulfilled/resolved [满足/解决] 状态
    - rejected [拒绝] 状态

- .then 和 .catch

  - resolved 的状态 promise 会回调后面 第一个 .then
  - rejected 的状态 promise 会回调后面 第一个 .catch
  - 任何一个 rejected 状态且后面没有 .catch 的 promise 都会造成 当前 运行时 环境的全局错误

- .then 和 .catch 返回的 promise 对象状态由 其执行结果【返回值】决定
  - 如果 throw new Error 【抛出错误】 会得到一个新的 rejected 状态 promise 对象
  - 同理，如果 return 会得到一个新的 resolved 状态的 promise 对象
  - 如果返回了一个 promise 对象，其状态与 新的 promise 状态一致

## 异步：异步编程之 async/await

- async function 是 promise 的语法糖 封装
- 异步编程的终极解决方案： 以同步的方式写异步

  - await 可以暂停 async funciton 的执行
  - awiat 关键字 可以 以同步的写法 获取 Promise 的执行结果
  - try catch 可以捕捉到 await 关键字 所得到 的错误

- async/await 是成对出现的，没有 async 只有 await 会报错
- 一个穿越事件循环的 function

## 问题记录

1. try catch 无法捕捉到 异步任务函数 throw new Error(如 setTimerout):

   > try catch 是依赖调用栈 ，只能捕捉到 依赖调用栈以上的函数。
   > [异步任务由 eventloop 加入任务队列，并取出入栈(js 主进程)执行，而当 task 取出执行的时候， 上下文环境已经改变，所以 无法捕获 task 的错误。]
   > 简单来说，异步，已经脱离了当前当前的主线程； 可以想象成在一个新的定时任务里去执行的；只是能与主线程共享内存，堆栈等
   > 解决：
   >
   > 1. async 中，可以正确 捕捉到 await 关键字 所得到 的错误
   > 2. nodejs 中， 使用 process.on（'uncaughtException'， function （err） ｛｝） 捕获 uncaughtException 异常

```js
function main() {
  try {
    // throw new Error('fail')

    setTimeout(() => {
      throw new Error('async error')
    })
    // getError()
  } catch (error) {
    console.log('error', error)
  }
}

main()
// nodejs 中才可以捕捉 使用；
process.on('uncaughtException', function (err) {
  console.log(err, 'err')
})
```

> [S 异步错误捕获二三事](https://juejin.im/post/5cc15de5e51d456e68659340#heading-10)

> [驳《慎用 try catch》](https://juejin.im/post/5c199882f265da617464c745#heading-2)
